Workbook

Sheet Summary
A1: Project Pathfinder -- Take-private of Stride, Inc. (NYSE: LRN)
A2: Illustrative LBO built from public filings. Not investment advice.
A4: Key output | B4: Value | D4: Note
A5: Offer price per share | B5: =LBO!B46 -> 107.107 | D5: 30% premium to $82.39 (Oct 17, 2026)
A6: Entry enterprise value ($mm) | B6: =LBO!B59 -> 4028.2773 | D6: Net of ~$958mm cash + securities
A7: Entry EV / FY2026 EBITDA | B7: =LBO!B61 -> 6.977438 | D7: GAAP EBITDA; SBC not added back
A8: New debt ($mm) | B8: =LBO!B63 -> 2525.3057 | D8: Constrained by the 40% minimum equity rule
A9: New debt / EBITDA | B9: =LBO!B64 -> 4.3741189
A10: Sponsor equity ($mm) | B10: =LBO!B55 -> 1683.5371
A11: Leverage at exit (debt / EBITDA) | B11: =LBO!G39 -> 1.5018908 | D11: Shows how much debt the cash flow repays
A12: MOIC (5-year hold) | B12: =LBO!B73 -> 2.3006261 | D12: Exit at entry multiple -- no multiple expansion
A13: IRR (5-year hold) | B13: =LBO!B74 -> 0.18132449 | D13: Typical PE target: 20%+
A14: Sources = uses check | B14: =LBO!C56 -> balances
A17: Color key: blue = hard-coded input · black = formula · green = link to another tab · yellow = key output / lever
A18: To test a scenario, change the blue cells on the Assumptions tab (e.g. premium, max leverage, exit multiple change).

Sheet Assumptions
A1: Stride, Inc. (LRN) -- LBO Assumptions
A2: $ in millions except per share. Blue = hard-coded input, black = formula, yellow = key lever.
A4: Input | B4: Value | C4: Source / rationale
A5: Transaction
A6: Current share price ($) | B6: 82.39 | C6: Yahoo Finance chart data, pulled Oct 17, 2026 by market_data.py
A7: Shares outstanding (mm) | B7: 41.559845 | C7: 10-K cover page, as of Jul 31, 2026
A8: Takeover premium | B8: 0.3 | C8: Typical US take-private premium range is 25-40%
A9: Transaction fees (% of EV) | B9: 0.02 | C9: Advisory + financing fees, standard assumption
A10: Minimum cash left in business | B10: 100 | C10: Operating cash buffer (~4% of revenue)
A12: Balance sheet at close (Jun 30, 2026)
A13: Cash and equivalents | B13: 754.501 | C13: Source: Stride FY2026 earnings release (Aug 2026) / 10-K for FY ended Jun 30, 2026, sec.gov
A14: Marketable securities | B14: 203.499 | C14: Source: Stride FY2026 earnings release (Aug 2026) / 10-K for FY ended Jun 30, 2026, sec.gov
A15: Convertible senior notes (1.125%, due Sep 2027) | B15: 417.995 | C15: Source: Stride FY2026 earnings release (Aug 2026) / 10-K for FY ended Jun 30, 2026, sec.gov. Refinanced at close
A16: Finance lease liabilities | B16: 116.932 | C16: Source: Stride FY2026 earnings release (Aug 2026) / 10-K for FY ended Jun 30, 2026, sec.gov. Treated as debt, refinanced at close
A18: FY2026 actuals (fiscal year ended Jun 30, 2026)
A19: Revenue -- General Education | B19: 1417.785 | C19: Source: Stride FY2026 earnings release (Aug 2026) / 10-K for FY ended Jun 30, 2026, sec.gov
A20: Revenue -- Career Learning | B20: 1100.296 | C20: Source: Stride FY2026 earnings release (Aug 2026) / 10-K for FY ended Jun 30, 2026, sec.gov
A21: Income from operations (EBIT) | B21: 450.767 | C21: Source: Stride FY2026 earnings release (Aug 2026) / 10-K for FY ended Jun 30, 2026, sec.gov
A22: Depreciation & amortization | B22: 126.562 | C22: Source: Stride FY2026 earnings release (Aug 2026) / 10-K for FY ended Jun 30, 2026, sec.gov
A23: Capex (PP&E + capitalized software + curriculum) | B23: 78.846 | C23: Source: Stride FY2026 earnings release (Aug 2026) / 10-K for FY ended Jun 30, 2026, sec.gov: 0.6 + 61.6 + 16.7
A24: Stock-based compensation (memo, NOT added back) | B24: 40.255 | C24: Conservative: GAAP EBITDA used, so SBC is treated as a real cost a PE owner pays in cash
A26: Financing
A27: Max total debt / EBITDA | B27: 5 | C27: Typical leveraged-loan market ceiling for a B-rated borrower
A28: Minimum sponsor equity (% of funding need) | B28: 0.4 | C28: Lenders typically require 40-50% equity in current market
A29: Minimum EBITDA / interest at close | B29: 2 | C29: Rating-agency comfort level
A30: Term Loan B share of total debt | B30: 0.7 | C30: Remainder funded with senior notes
A31: Term Loan B interest rate | B31: 0.0775 | C31: SOFR (~4.25%) + 350bp spread
A32: Senior notes interest rate | B32: 0.09 | C32: B-rated high-yield context
A33: TLB mandatory amortization (% of original / yr) | B33: 0.01 | C33: Market standard for TLBs
A34: Excess cash flow sweep to TLB | B34: 1 | C34: 100% of free cash flow repays the TLB early
A36: Operating & exit
A37: Tax rate | B37: 0.25 | C37: FY2026 effective rate was ~23%; 25% is conservative
A38: Working capital investment (% of revenue change) | B38: 0.1 | C38: Receivables from school districts grow with revenue
A39: Exit multiple change vs. entry (x) | B39: 0 | C39: 0 = exit at the entry multiple (no multiple expansion)

Sheet LBO
A1: Stride, Inc. (LRN) -- Leveraged Buyout Model
A2: $ in millions. Fiscal years end June 30.
B4: FY2026A | C4: FY2027E | D4: FY2028E | E4: FY2029E | F4: FY2030E | G4: FY2031E
A5: Operating drivers
A6: General Education revenue growth | B6: =B14/1448.676-1 -> -0.021323609 | C6: -0.01 | D6: -0.01 | E6: 0 | F6: 0 | G6: 0
A7: Career Learning revenue growth | B7: =B15/956.641-1 -> 0.15016605 | C7: 0.1 | D7: 0.09 | E7: 0.08 | F7: 0.07 | G7: 0.06
A8: EBITDA margin | B8: =B18/B16 -> 0.2292734 | C8: =B8 -> 0.2292734 | D8: =C8 -> 0.2292734 | E8: =D8 -> 0.2292734 | F8: =E8 -> 0.2292734 | G8: =F8 -> 0.2292734
A9: D&A % of revenue | B9: =-B19/B16 -> 0.05026129 | C9: =B9 -> 0.05026129 | D9: =C9 -> 0.05026129 | E9: =D9 -> 0.05026129 | F9: =E9 -> 0.05026129 | G9: =F9 -> 0.05026129
A10: Capex % of revenue | B10: =Assumptions!$B$23/B16 -> 0.03131194 | C10: =B10 -> 0.03131194 | D10: =C10 -> 0.03131194 | E10: =D10 -> 0.03131194 | F10: =E10 -> 0.03131194 | G10: =F10 -> 0.03131194
A12: Income statement & free cash flow
A14: General Education revenue | B14: =Assumptions!$B$19 -> 1417.785 | C14: =B14*(1+C6) -> 1403.6072 | D14: =C14*(1+D6) -> 1389.5711 | E14: =D14*(1+E6) -> 1389.5711 | F14: =E14*(1+F6) -> 1389.5711 | G14: =F14*(1+G6) -> 1389.5711
A15: Career Learning revenue | B15: =Assumptions!$B$20 -> 1100.296 | C15: =B15*(1+C7) -> 1210.3256 | D15: =C15*(1+D7) -> 1319.2549 | E15: =D15*(1+E7) -> 1424.7953 | F15: =E15*(1+F7) -> 1524.531 | G15: =F15*(1+G7) -> 1616.0028
A16: Total revenue | B16: =B14+B15 -> 2518.081 | C16: =C14+C15 -> 2613.9327 | D16: =D14+D15 -> 2708.826 | E16: =E14+E15 -> 2814.3664 | F16: =F14+F15 -> 2914.102 | G16: =G14+G15 -> 3005.5739
A17: Revenue growth | B17: =B16/2405.317-1 -> 0.046881139 | C17: =C16/B16-1 -> 0.038065396 | D17: =D16/C16-1 -> 0.036302859 | E17: =E16/D16-1 -> 0.038961673 | F17: =F16/E16-1 -> 0.035438055 | G17: =G16/F16-1 -> 0.031389381
A18: EBITDA | B18: =Assumptions!$B$21+Assumptions!$B$22 -> 577.329 | C18: =C16*C8 -> 599.30526 | D18: =D16*D8 -> 621.06175 | E18: =E16*E8 -> 645.25936 | F18: =F16*F8 -> 668.12609 | G18: =G16*G8 -> 689.09816
A19: Less: D&A | B19: =-Assumptions!$B$22 -> -126.562 | C19: =-C16*C9 -> -131.37963 | D19: =-D16*D9 -> -136.14909 | E19: =-E16*E9 -> -141.45369 | F19: =-F16*F9 -> -146.46653 | G19: =-G16*G9 -> -151.06402
A20: EBIT | B20: =B18+B19 -> 450.767 | C20: =C18+C19 -> 467.92562 | D20: =D18+D19 -> 484.91266 | E20: =E18+E19 -> 503.80567 | F20: =F18+F19 -> 521.65956 | G20: =G18+G19 -> 538.03413
A21: Less: Interest expense | C21: =-(B34*Assumptions!$B$31+B35*Assumptions!$B$32) -> -205.18109 | D21: =-(C34*Assumptions!$B$31+C35*Assumptions!$B$32) -> -186.81316 | E21: =-(D34*Assumptions!$B$31+D35*Assumptions!$B$32) -> -166.24343 | F21: =-(E34*Assumptions!$B$31+E35*Assumptions!$B$32) -> -143.30746 | G21: =-(F34*Assumptions!$B$31+F35*Assumptions!$B$32) -> -117.80912
A22: Pre-tax income | C22: =C20+C21 -> 262.74453 | D22: =D20+D21 -> 298.0995 | E22: =E20+E21 -> 337.56224 | F22: =F20+F21 -> 378.3521 | G22: =G20+G21 -> 420.22501
A23: Less: Taxes | C23: =-MAX(C22,0)*Assumptions!$B$37 -> -65.686134 | D23: =-MAX(D22,0)*Assumptions!$B$37 -> -74.524876 | E23: =-MAX(E22,0)*Assumptions!$B$37 -> -84.390559 | F23: =-MAX(F22,0)*Assumptions!$B$37 -> -94.588026 | G23: =-MAX(G22,0)*Assumptions!$B$37 -> -105.05625
A24: Net income | C24: =C22+C23 -> 197.0584 | D24: =D22+D23 -> 223.57463 | E24: =E22+E23 -> 253.17168 | F24: =F22+F23 -> 283.76408 | G24: =G22+G23 -> 315.16876
A25: Plus: D&A | C25: =-C19 -> 131.37963 | D25: =-D19 -> 136.14909 | E25: =-E19 -> 141.45369 | F25: =-F19 -> 146.46653 | G25: =-G19 -> 151.06402
A26: Less: Capex | C26: =-C16*C10 -> -81.847304 | D26: =-D16*D10 -> -84.818595 | E26: =-E16*E10 -> -88.12327 | F26: =-F16*F10 -> -91.246187 | G26: =-G16*G10 -> -94.110348
A27: Less: Increase in working capital | C27: =-(C16-B16)*Assumptions!$B$38 -> -9.585175 | D27: =-(D16-C16)*Assumptions!$B$38 -> -9.4893233 | E27: =-(E16-D16)*Assumptions!$B$38 -> -10.554039 | F27: =-(F16-E16)*Assumptions!$B$38 -> -9.9735671 | G27: =-(G16-F16)*Assumptions!$B$38 -> -9.1471858
A28: Levered free cash flow | C28: =C24+C25+C26+C27 -> 237.00555 | D28: =D24+D25+D26+D27 -> 265.4158 | E28: =E24+E25+E26+E27 -> 295.94805 | F28: =F24+F25+F26+F27 -> 329.01085 | G28: =G24+G25+G26+G27 -> 362.97525
A30: Debt schedule
A31: Term Loan B -- beginning | C31: =B34 -> 1767.714 | D31: =C34 -> 1530.7084 | E31: =D34 -> 1265.2927 | F31: =E34 -> 969.3446 | G31: =F34 -> 640.33375
A32: Mandatory amortization | C32: =-MIN($B$53*Assumptions!$B$33,C31) -> -17.67714 | D32: =-MIN($B$53*Assumptions!$B$33,D31) -> -17.67714 | E32: =-MIN($B$53*Assumptions!$B$33,E31) -> -17.67714 | F32: =-MIN($B$53*Assumptions!$B$33,F31) -> -17.67714 | G32: =-MIN($B$53*Assumptions!$B$33,G31) -> -17.67714
A33: Optional repayment (cash sweep) | C33: =-MIN(MAX(C28+C32,0)*Assumptions!$B$34,C31+C32) -> -219.32841 | D33: =-MIN(MAX(D28+D32,0)*Assumptions!$B$34,D31+D32) -> -247.73866 | E33: =-MIN(MAX(E28+E32,0)*Assumptions!$B$34,E31+E32) -> -278.27091 | F33: =-MIN(MAX(F28+F32,0)*Assumptions!$B$34,F31+F32) -> -311.33371 | G33: =-MIN(MAX(G28+G32,0)*Assumptions!$B$34,G31+G32) -> -345.29811
A34: Term Loan B -- ending | B34: =B53 -> 1767.714 | C34: =C31+C32+C33 -> 1530.7084 | D34: =D31+D32+D33 -> 1265.2927 | E34: =E31+E32+E33 -> 969.3446 | F34: =F31+F32+F33 -> 640.33375 | G34: =G31+G32+G33 -> 277.3585
A35: Senior notes | B35: =B54 -> 757.59172 | C35: =B35 -> 757.59172 | D35: =C35 -> 757.59172 | E35: =D35 -> 757.59172 | F35: =E35 -> 757.59172 | G35: =F35 -> 757.59172
A36: Total debt | B36: =B34+B35 -> 2525.3057 | C36: =C34+C35 -> 2288.3002 | D36: =D34+D35 -> 2022.8844 | E36: =E34+E35 -> 1726.9363 | F36: =F34+F35 -> 1397.9255 | G36: =G34+G35 -> 1034.9502
A37: Cash balance | B37: =Assumptions!$B$10 -> 100 | C37: =B37+C28+C32+C33 -> 100 | D37: =C37+D28+D32+D33 -> 100 | E37: =D37+E28+E32+E33 -> 100 | F37: =E37+F28+F32+F33 -> 100 | G37: =F37+G28+G32+G33 -> 100
A38: Net debt | B38: =B36-B37 -> 2425.3057 | C38: =C36-C37 -> 2188.3002 | D38: =D36-D37 -> 1922.8844 | E38: =E36-E37 -> 1626.9363 | F38: =F36-F37 -> 1297.9255 | G38: =G36-G37 -> 934.95021
A39: Total debt / EBITDA | B39: =B36/B18 -> 4.3741189 | C39: =C36/C18 -> 3.8182548 | D39: =D36/D18 -> 3.2571389 | E39: =E36/E18 -> 2.6763445 | F39: =F36/F18 -> 2.0923078 | G39: =G36/G18 -> 1.5018908
A40: Net debt / EBITDA | B40: =B38/B18 -> 4.2009075 | C40: =C38/C18 -> 3.6513949 | D40: =D38/D18 -> 3.0961243 | E40: =E38/E18 -> 2.521368 | F40: =F38/F18 -> 1.9426355 | G40: =G38/G18 -> 1.3567736
A41: EBITDA / interest | C41: =IF(C21=0,0,C18/-C21) -> 2.9208601 | D41: =IF(D21=0,0,D18/-D21) -> 3.3245075 | E41: =IF(E21=0,0,E18/-E21) -> 3.8814126 | F41: =IF(F21=0,0,F18/-F21) -> 4.6621864 | G41: =IF(G21=0,0,G18/-G21) -> 5.8492769
A44: Sources & uses at close
A45: Uses
A46: Offer price per share ($) | B46: =Assumptions!$B$6*(1+Assumptions!$B$8) -> 107.107
...

Sheet Sensitivity
A1: Returns sensitivity -- exit multiple vs. holding period
A2: Every cell is a live formula off the LBO tab. Debt paydown path doesn't depend on exit multiple.
A4: IRR: exit multiple (rows) vs. exit year | F4: MOIC: exit multiple (rows) vs. exit year
A5: Exit EV / EBITDA | B5: FY2029E | C5: FY2030E | D5: FY2031E | F5: Exit EV / EBITDA | G5: FY2029E | H5: FY2030E | I5: FY2031E
A6: =LBO!$B$61+(-2) -> 4.977438 | B6: =((A6*LBO!$E$18-LBO!$E$38)/LBO!$B$55)^(1/3)-1 -> -0.019944247 | C6: =((A6*LBO!$F$18-LBO!$F$38)/LBO!$B$55)^(1/4)-1 -> 0.047590477 | D6: =((A6*LBO!$G$18-LBO!$G$38)/LBO!$B$55)^(1/5)-1 -> 0.081855684 | F6: =LBO!$B$61+(-2) -> 4.977438 | G6: =(F6*LBO!$E$18-LBO!$E$38)/LBO!$B$55 -> 0.94135264 | H6: =(F6*LBO!$F$18-LBO!$F$38)/LBO!$B$55 -> 1.2043873 | I6: =(F6*LBO!$G$18-LBO!$G$38)/LBO!$B$55 -> 1.4819947
A7: =LBO!$B$61+(-1) -> 5.977438 | B7: =((A7*LBO!$E$18-LBO!$E$38)/LBO!$B$55)^(1/3)-1 -> 0.098241993 | C7: =((A7*LBO!$F$18-LBO!$F$38)/LBO!$B$55)^(1/4)-1 -> 0.12490152 | D7: =((A7*LBO!$G$18-LBO!$G$38)/LBO!$B$55)^(1/5)-1 -> 0.1359326 | F7: =LBO!$B$61+(-1) -> 5.977438 | G7: =(F7*LBO!$E$18-LBO!$E$38)/LBO!$B$55 -> 1.3246286 | H7: =(F7*LBO!$F$18-LBO!$F$38)/LBO!$B$55 -> 1.6012458 | I7: =(F7*LBO!$G$18-LBO!$G$38)/LBO!$B$55 -> 1.8913104
A8: =LBO!$B$61+(0) -> 6.977438 | B8: =((A8*LBO!$E$18-LBO!$E$38)/LBO!$B$55)^(1/3)-1 -> 0.19533014 | C8: =((A8*LBO!$F$18-LBO!$F$38)/LBO!$B$55)^(1/4)-1 -> 0.18892523 | D8: =((A8*LBO!$G$18-LBO!$G$38)/LBO!$B$55)^(1/5)-1 -> 0.18132449 | F8: =LBO!$B$61+(0) -> 6.977438 | G8: =(F8*LBO!$E$18-LBO!$E$38)/LBO!$B$55 -> 1.7079046 | H8: =(F8*LBO!$F$18-LBO!$F$38)/LBO!$B$55 -> 1.9981044 | I8: =(F8*LBO!$G$18-LBO!$G$38)/LBO!$B$55 -> 2.3006261
A9: =LBO!$B$61+(1) -> 7.977438 | B9: =((A9*LBO!$E$18-LBO!$E$38)/LBO!$B$55)^(1/3)-1 -> 0.27878396 | C9: =((A9*LBO!$F$18-LBO!$F$38)/LBO!$B$55)^(1/4)-1 -> 0.24401237 | D9: =((A9*LBO!$G$18-LBO!$G$38)/LBO!$B$55)^(1/5)-1 -> 0.22065235 | F9: =LBO!$B$61+(1) -> 7.977438 | G9: =(F9*LBO!$E$18-LBO!$E$38)/LBO!$B$55 -> 2.0911806 | H9: =(F9*LBO!$F$18-LBO!$F$38)/LBO!$B$55 -> 2.3949629 | I9: =(F9*LBO!$G$18-LBO!$G$38)/LBO!$B$55 -> 2.7099418
A10: =LBO!$B$61+(2) -> 8.977438 | B10: =((A10*LBO!$E$18-LBO!$E$38)/LBO!$B$55)^(1/3)-1 -> 0.35257061 | C10: =((A10*LBO!$F$18-LBO!$F$38)/LBO!$B$55)^(1/4)-1 -> 0.29262309 | D10: =((A10*LBO!$G$18-LBO!$G$38)/LBO!$B$55)^(1/5)-1 -> 0.25548129 | F10: =LBO!$B$61+(2) -> 8.977438 | G10: =(F10*LBO!$E$18-LBO!$E$38)/LBO!$B$55 -> 2.4744566 | H10: =(F10*LBO!$F$18-LBO!$F$38)/LBO!$B$55 -> 2.7918215 | I10: =(F10*LBO!$G$18-LBO!$G$38)/LBO!$B$55 -> 3.1192575
A13: Reading the grid: the yellow cell matches the base case on the LBO tab. Moving up one row = selling at a lower multiple than you paid -- the main risk in any LBO.

Sheet Screen Results
A1: Take-private screen: top 25 of 107 candidates, ranked by base-case IRR
A2: Values (not formulas) produced by screen_and_rank.py from SEC EDGAR XBRL data. Stride's row uses FY2025 data from the screen; the LBO tab uses FY2026 actuals.
A4: Rank | B4: Company | C4: Ticker | D4: Industry (SIC) | E4: Mkt cap ($mm) | F4: EBITDA ($mm) | G4: EBITDA margin | H4: Entry EV/EBITDA | I4: MOIC | J4: IRR
A5: 1 | B5: Stride, Inc. | C5: LRN | D5: Services-Educational Services | E5: 3424.1156 | F5: 474.763 | G5: 0.19738064 | H5: 9.2076137 | I5: 2.7879193 | J5: 0.22759762
A6: 2 | B6: MIMEDX GROUP, INC. | C6: MDXG | D6: Surgical & Medical Instruments & Apparatus | E6: 645.71887 | F6: 78.768 | G6: 0.18815661 | H6: 8.7765785 | I6: 2.5804983 | J6: 0.20876177
A7: 3 | B7: NICE LTD. | C7: NICE | D7: Services-Prepackaged Software | E7: 6777.8575 | F7: 844.802 | G7: 0.2868209 | H7: 9.9808319 | I7: 2.5219546 | J7: 0.20322668
A8: 4 | B8: INNOVIVA, INC. | C8: INVA | D8: Pharmaceutical Preparations | E8: 1501.2612 | F8: 163.745 | G8: 0.39808863 | H8: 10.128123 | I8: 2.4915458 | J8: 0.20031097
A9: 5 | B9: YELP INC | C9: YELP | D9: Services-Personal Services | E9: 1078.7608 | F9: 234.613 | G9: 0.16015031 | H9: 6.0024254 | I9: 2.3999547 | J9: 0.1913534
A10: 6 | B10: GENTEX CORPORATION | C10: GNTX | D10: Motor Vehicle Parts & Accessories | E10: 4426.4568 | F10: 577.97752 | G10: 0.22806479 | H10: 9.7040939 | I10: 2.3798644 | J10: 0.18935209
A11: 7 | B11: HARMONY BIOSCIENCES HOLDINGS, INC. | C11: HRMY | D11: Pharmaceutical Preparations | E11: 2210.0711 | F11: 208.469 | G11: 0.24004638 | H11: 10.957281 | I11: 2.3398256 | J11: 0.18532297
A12: 8 | B12: PERDOCEO EDUCATION CORP | C12: PRDO | D12: Services-Educational Services | E12: 2110.7241 | F12: 237.627 | G12: 0.28085111 | H12: 11.08027 | I12: 2.1815226 | J12: 0.1688316
A13: 9 | B13: KORN FERRY | C13: KFY | D13: Services-Employment Agencies | E13: 3984.4329 | F13: 473.587 | G13: 0.16115851 | H13: 9.7970421 | I13: 2.1125462 | J13: 0.16134497
A14: 10 | B14: Bristow Group Inc. | C14: VTOL | D14: Air Transportation, Nonscheduled | E14: 1145.3669 | F14: 229.075 | G14: 0.1536888 | H14: 8.1817001 | I14: 2.1120468 | J14: 0.16129005
A15: 11 | B15: Abercrombie & Fitch Co. | C15: ANF | D15: Retail-Family Clothing Stores | E15: 6503.4926 | F15: 854.164 | G15: 0.16219458 | H15: 9.0088091 | I15: 2.1005545 | J15: 0.16002351
A16: 12 | B16: GENPACT LIMITED | C16: G | D16: Services-Management Consulting Services | E16: 6260.962 | F16: 820.874 | G16: 0.16159322 | H16: 10.754045 | I16: 2.075271 | J16: 0.15721742
... A29: 25 | B29: ARMSTRONG WORLD INDUSTRIES, INC. | C29: AWI | D29: Plastics Products, Nec | E29: 7106.9168 | F29: 551.3 | G29: 0.34014067 | H29: 17.273158 | I29: 1.795033 | J29: 0.12412469
B32: Screening funnel
B33: US companies with FY2025 XBRL financials | E33: 6154
B34: Pass loose pre-screen (EBITDA $25M-$2B, FCF > 0, margin > 8%) | E34: 1034
B35: With a ticker and listed | E35: 940
B36: Debt data complete (manual checks applied) | E36: 896
B37: Excl. financials, utilities, oil & gas, shipping, LPs | E37: 707
B38: Market cap >= $250M | E38: 570
B39: EBITDA $50M-$1B | E39: 457
B40: EBITDA margin >= 15% | E40: 263
B41: FCF / EBITDA >= 40% | E41: 216
B42: Net debt / EBITDA <= 2.0x | E42: 159
B43: Revenue growth -5% to +40% | E43: 133
B44: Profitable both years, no EBIT spike | E44: 107
